Workbook

Sheet Data
A1: Дата | B1: Темп Совокупной Инфляции | C1: Инфляционные ожидания | D1: Темп прироста ВВП | E1: Разрыв выпуска | F1: Темп Базовой Инфляции | G1: Composite Leading Indicator (CLI)
A2: 31412 | B2: ='Темп Совокупной Инфляции'!C9 -> 2.02 | C2: ='Инфляционные ожидания'!D8 -> 0.426 | D2: ='Темп роста ВВП'!D11 -> 0.206 | E2: ='Разрыв выпуска'!F15 -> 0 | F2: ='Темп Базовой Инфляции'!D10 -> 0.086 | G2: 100.0174
A3: 31502 | B3: ='Темп Совокупной Инфляции'!C10 -> 2.22 | C3: ='Инфляционные ожидания'!D9 -> 0.318 | D3: ='Темп роста ВВП'!D12 -> 0.165 | E3: ='Разрыв выпуска'!F16 -> -0.003 | F3: ='Темп Базовой Инфляции'!D11 -> 0.083 | G3: 99.5645
A4: 31593 | B4: ='Темп Совокупной Инфляции'!C11 -> 1.69 | C4: ='Инфляционные ожидания'!D10 -> 0 | D4: ='Темп роста ВВП'!D13 -> 0.061 | E4: ='Разрыв выпуска'!F17 -> -0.014 | F4: ='Темп Базовой Инфляции'!D12 -> 0.08 | G4: 98.9463
A5: 31685 | B5: ='Темп Совокупной Инфляции'!C12 -> 2.61 | C5: ='Инфляционные ожидания'!D11 -> 0.373 | D5: ='Темп роста ВВП'!D14 -> 0.02 | E5: ='Разрыв выпуска'!F18 -> -0.021 | F5: ='Темп Базовой Инфляции'!D13 -> 0.078 | G5: 98.8212
A6: 31777 | B6: ='Темп Совокупной Инфляции'!C13 -> 2.78 | C6: ='Инфляционные ожидания'!D12 -> 0.334 | D6: ='Темп роста ВВП'!D15 -> 0.1 | E6: ='Разрыв выпуска'!F19 -> -0.013 | F6: ='Темп Базовой Инфляции'!D14 -> 0.079 | G6: 99.4108
A7: 31867 | B7: ='Темп Совокупной Инфляции'!C14 -> 2.03 | C7: ='Инфляционные ожидания'!D13 -> 0.351 | D7: ='Темп роста ВВП'!D16 -> 0.117 | E7: ='Разрыв выпуска'!F20 -> -0.013 | F7: ='Темп Базовой Инфляции'!D15 -> 0.075 | G7: 100.0709
A8: 31958 | B8: ='Темп Совокупной Инфляции'!C15 -> 1.55 | C8: ='Инфляционные ожидания'!D14 -> 0.338 | D8: ='Темп роста ВВП'!D17 -> 0.197 | E8: ='Разрыв выпуска'!F21 -> -0.006 | F8: ='Темп Базовой Инфляции'!D16 -> 0.073 | G8: 100.8311
A9: 32050 | B9: ='Темп Совокупной Инфляции'!C16 -> 1.74 | C9: ='Инфляционные ожидания'!D15 -> 0.331 | D9: ='Темп роста ВВП'!D18 -> 0.272 | E9: ='Разрыв выпуска'!F22 -> 0.003 | F9: ='Темп Базовой Инфляции'!D17 -> 0.069 | G9: 101.2372
A10: 32142 | B10: ='Темп Совокупной Инфляции'!C17 -> 1.71 | C10: ='Инфляционные ожидания'!D16 -> 0.346 | D10: ='Темп роста ВВП'!D19 -> 0.286 | E10: ='Разрыв выпуска'!F23 -> 0.014 | F10: ='Темп Базовой Инфляции'!D18 -> 0.069 | G10: 101.0349
A11: 32233 | B11: ='Темп Совокупной Инфляции'!C18 -> 1.68 | C11: ='Инфляционные ожидания'!D17 -> 0.32 | D11: ='Темп роста ВВП'!D20 -> 0.262 | E11: ='Разрыв выпуска'!F24 -> 0.01 | F11: ='Темп Базовой Инфляции'!D19 -> 0.074 | G11: 101.2228
A12: 32324 | B12: ='Темп Совокупной Инфляции'!C19 -> 1.86 | C12: ='Инфляционные ожидания'!D18 -> 0.325 | D12: ='Темп роста ВВП'!D21 -> 0.188 | E12: ='Разрыв выпуска'!F25 -> 0.003 | F12: ='Темп Базовой Инфляции'!D20 -> 0.077 | G12: 101.7787
A13: 32416 | B13: ='Темп Совокупной Инфляции'!C20 -> 1.83 | C13: ='Инфляционные ожидания'!D19 -> 0.34 | D13: ='Темп роста ВВП'!D22 -> 0.143 | E13: ='Разрыв выпуска'!F26 -> 0.003 | F13: ='Темп Базовой Инфляции'!D21 -> 0.079 | G13: 102.2747
... A156: 45473 | B156: ='Темп Совокупной Инфляции'!C163 -> 1 | C156: ='Инфляционные ожидания'!D162 -> 0.1 | D156: ='Темп роста ВВП'!D165 -> 0.041 | E156: ='Разрыв выпуска'!F169 -> -0.007 | F156: ='Темп Базовой Инфляции'!D164 -> 0.19 | G156: 99.4647

Sheet Вопрос 2
B1: Мин | C1: Макс | D1: Среднее | E1: Медиана | F1: Мода | G1: Ст Откл | H1: Асимметрия
A2: Темп Совокупной Инфляции | B2: -1.825 | C2: 3.698 | D2: 0.794 | E2: 0.654 | F2: 0.054 | G2: 0.713 | H2: 0.739
A3: Инфляционные ожидания | B3: 0.005 | C3: 0.429 | D3: 0.141 | E3: 0.110 | F3: 0.105 | G3: 0.089 | H3: 1.747
A4: Темп роста ВВП | B4: -0.223 | C4: 0.496 | D4: 0.129 | E4: 0.126 | F4: 0.104 | G4: 0.078 | H4: -0.167
A5: Разрыв выпуска | B5: -0.070 | C5: 0.032 | D5: 0.000 | E5: 0.000 | F5: 0.000 | G5: 0.012 | H5: -1.709
A6: Темп Базовой Инфляции | B6: -0.033 | C6: 0.037 | D6: 0.001 | E6: 0.001 | F6: 0.000 | G6: 0.007 | H6: 0.043
A7: Composite Leading Indicator (CLI) | B7: 97.242 | C7: 102.351 | D7: 99.995 | E7: 99.960 | F7: 98.900 | G7: 0.909 | H7: -0.145

Sheet Вопрос 3-6
A1: Метрика | B1: Spec 1 (Headline Infation) | C1: Spec 2 (Headline Infation) | D1: Spec 1 (Core inflation) | E1: Spec 2 (Core inflation) | F1: Spec 3 | G1: Spec 4 | H1: Spec 5 | I1: Spec 6 | J1: Spec 7
A2: R-squared | B2: 0.264 | C2: 0.154 | D2: 0.346 | E2: 0.006 | F2: 0.005 | G2: 0.004 | H2: 0.347 | I2: 0.353 | J2: 0.390
A3: Adjusted R-squared | B3: 0.243 | C3: 0.148 | D3: 0.328 | E3: -0.001 | F3: -0.001 | G3: -0.003 | H3: 0.324 | I3: 0.330 | J3: 0.368
A4: F-statistic (p-value) | B4: 12.57 (p < 0.001) | C4: 26.75 (p < 0.001) | D4: 18.67 (p < 0.001) | E4: 0.8807 (p = 0.350) | F4: 0.7854 (p = 0.377) | G4: 0.6147 (p = 0.434) | H4: 14.88 (p < 0.001) | I4: 15.28 -0.0250 (p < 0.001) | J4: 17.88 (p < 0.001)
A5: AIC | B5: 313.0 | C5: 294.4 | D5: -976.8 | E5: -1046.0 | F5: -1039.0 | G5: -1015.0 | H5: -974.9 | I5: -976.3 | J5: -984.8
A6: BIC | B6: 327.9 | C6: 300.4 | D6: -961.8 | E6: -1040.0 | F6: -1032.0 | G6: -1009.0 | H6: -957.0 | I6: -958.4 | J6: -966.9
A7: Durbin-Watson (DW) | B7: 1.262 | C7: 1.375 | D7: 1.169 | E7: 1.347 | F7: 1.350 | G7: 1.355 | H7: 1.162 | I7: 1.221 | J7: 1.267
A8: Статистика Джарка-Бера (p-value) | B8: 73.600 (p < 0.001) | C8: 102.997 (p < 0.001) | D8: 61.065 (p < 0.001) | E8: 250.402 (p < 0.001) | F8: 240.280 (p < 0.001) | G8: 231.056 (p < 0.001) | H8: 60.979 (p < 0.001) | I8: 64.463 (p < 0.001) | J8: 65.476 (p < 0.001)
A9: Коэффициенты
A10: const | B10: -0.0305 (p = 0.600) | C10: 0.3780 (p < 0.001) | D10: 0.0002 (p = 0.827) | E10: 0.0007 (p = 0.270) | F10: -7.666e-05 (p = 0.946) | G10: 0.0009 (p = 0.166) | H10: 0.0002 (p = 0.822) | I10: -0.0013 (p = 0.349) | J10: -0.2360 (p = 0.002)
A11: t-t-1 | B11: -0.6594 (p < 0.001) | C11: - | D11: -0.7585 (p < 0.001) | E11: - | F11: - | G11: - | H11: -0.7536 (p < 0.001) | I11: -0.7765 (p < 0.001) | J11: -0.7625 (p < 0.001)
A12: t-1-t-2 | B12: -0.3597 (p = 0.001) | C12: - | D12: -0.5693 (p < 0.001) | E12: - | F12: - | G12: - | H12: -0.5632 (p < 0.001) | I12: -0.5889 (p < 0.001) | J12: -0.5758 (p < 0.001)
A13: t-2-t-3 | B13: -0.1994 (p = 0.072) | C13: - | D13: -0.4095 (p < 0.001) | E13: - | F13: - | G13: - | H13: -0.4044 (p < 0.001) | I13: -0.4325 (p < 0.001) | J13: -0.4153 (p < 0.001)
A14: t-3-t-4 | B14: -0.1189 (p = 0.206) | C14: - | D14: -0.2671 (p = 0.004) | E14: - | F14: - | G14: - | H14: -0.2665 (p = 0.005) | I14: -0.2811 (p = 0.003) | J14: -0.2682 (p = 0.003)
A15: x1_t-1 | B15: - | C15: - | D15: - | E15: - | F15: - | G15: - | H15: -0.0250 (p = 0.685) | I15: - | J15: -
A16: x2_t-1 | B16: - | C16: - | D16: - | E16: - | F16: - | G16: - | H16: - | I16: 0.0111 (p = 0.227) | J16: -
A17: x3_t-1 | B17: - | C17: - | D17: - | E17: - | F17: - | G17: - | H17: - | I17: - | J17: 0.0024 (p = 0.002)
A18: mean_last_4_quarters | B18: - | C18: 0.4974 (p < 0.001) | D18: - | E18: 0.1197 (p = 0.350) | F18: - | G18: - | H18: - | I18: - | J18: -
A19: Инфляционные ожидания | B19: - | C19: - | D19: - | E19: - | F19: 0.0060 (p = 0.377) | G19: - | H19: - | I19: - | J19: -
A20: Темп прироста ожиданий | B20: - | C20: - | D20: - | E20: - | F20: - | G20: 0.0109 (p = 0.434) | H20: - | I20: - | J20: -

Sheet Темп Совокупной Инфляции
B2: Источник данных: https://cbonds.ru/indexes/41423/
B4: Мы взяли данные по совокупной инфляции в годовом выражении (индекс отражает изменение уровня потребительских цен к предыдущему кварталу).
B8: Дата | C8: Темп Совокупной Инфляции
B9: 31412 | C9: 2.02
B10: 31502 | C10: 2.22
B11: 31593 | C11: 1.69
B12: 31685 | C12: 2.61
B13: 31777 | C13: 2.78
B14: 31867 | C14: 2.03
B15: 31958 | C15: 1.55
B16: 32050 | C16: 1.74
B17: 32142 | C17: 1.71
B18: 32233 | C18: 1.68
B19: 32324 | C19: 1.86
B20: 32416 | C20: 1.83
... B164: 45565 | C164: 0.2

Sheet Инфляционные ожидания
B2: Источник данных: https://cbonds.ru/indexes/92578/
B4: Мы взяли инфляционные ожидания (разница между номинальной доходностью 10-летних облигаций и доходностью 10-летних облигаций, индексированной на инфляцию). Для аннуализации данных мы использовали формулу: (1 + r)^n - 1 , которую взяли Investopedia
B7: Дата | C7: Инфляционные ожидания | D7: Аннуализированные Инфляционные ожидания.
B8: 31412 | C8: 9.27 | D8: =ROUND((1+C8/100)^4 -1, 3) -> 0.426
B9: 31502 | C9: 7.14 | D9: =ROUND((1+C9/100)^4 -1, 3) -> 0.318
B10: 31593 | D10: =ROUND((1+C10/100)^4 -1, 3) -> 0
B11: 31685 | C11: 8.25 | D11: =ROUND((1+C11/100)^4 -1, 3) -> 0.373
B12: 31777 | C12: 7.48 | D12: =ROUND((1+C12/100)^4 -1, 3) -> 0.334
B13: 31867 | C13: 7.82 | D13: =ROUND((1+C13/100)^4 -1, 3) -> 0.351
B14: 31958 | C14: 7.56 | D14: =ROUND((1+C14/100)^4 -1, 3) -> 0.338
B15: 32050 | C15: 7.42 | D15: =ROUND((1+C15/100)^4 -1, 3) -> 0.331
B16: 32142 | C16: 7.72 | D16: =ROUND((1+C16/100)^4 -1, 3) -> 0.346
B17: 32233 | C17: 7.18 | D17: =ROUND((1+C17/100)^4 -1, 3) -> 0.32
B18: 32324 | C18: 7.29 | D18: =ROUND((1+C18/100)^4 -1, 3) -> 0.325
B19: 32416 | C19: 7.6 | D19: =ROUND((1+C19/100)^4 -1, 3) -> 0.34
B20: 32508 | C20: 8.68 | D20: =ROUND((1+C20/100)^4 -1, 3) -> 0.395
B21: 32598 | C21: 9.37 | D21: =ROUND((1+C21/100)^4 -1, 3) -> 0.431
B22: 32689 | C22: 9.02 | D22: =ROUND((1+C22/100)^4 -1, 3) -> 0.413
... B163: 45565 | C163: 2.34 | D163: =ROUND((1+C163/100)^4 -1, 3) -> 0.097

Sheet Темп роста ВВП
B2: Источник данных: https://cbonds.ru/indexes/41433/
B4: Мы взяли данные по темпу роста ВВП. Для аннуализации данных мы использовали ту же формулу: (1 + r)^n - 1
B10: Дата | C10: Темп роста ВВП | D10: Аннуализированный темп прироста ВВП
B11: 31412 | C11: 4.8 | D11: =ROUND((1+C11/100)^4 -1, 3) -> 0.206
B12: 31502 | C12: 3.9 | D12: =ROUND((1+C12/100)^4 -1, 3) -> 0.165
B13: 31593 | C13: 1.5 | D13: =ROUND((1+C13/100)^4 -1, 3) -> 0.061
B14: 31685 | C14: 0.5 | D14: =ROUND((1+C14/100)^4 -1, 3) -> 0.02
B15: 31777 | C15: 2.4 | D15: =ROUND((1+C15/100)^4 -1, 3) -> 0.1
B16: 31867 | C16: 2.8 | D16: =ROUND((1+C16/100)^4 -1, 3) -> 0.117
B17: 31958 | C17: 4.6 | D17: =ROUND((1+C17/100)^4 -1, 3) -> 0.197
B18: 32050 | C18: 6.2 | D18: =ROUND((1+C18/100)^4 -1, 3) -> 0.272
B19: 32142 | C19: 6.5 | D19: =ROUND((1+C19/100)^4 -1, 3) -> 0.286
B20: 32233 | C20: 6 | D20: =ROUND((1+C20/100)^4 -1, 3) -> 0.262
B21: 32324 | C21: 4.4 | D21: =ROUND((1+C21/100)^4 -1, 3) -> 0.188
B22: 32416 | C22: 3.4 | D22: =ROUND((1+C22/100)^4 -1, 3) -> 0.143
... B165: 45473 | C165: 1 | D165: =ROUND((1+C165/100)^4 -1, 3) -> 0.041

Sheet Разрыв выпуска
B2: Источник данных: https://cbonds.ru/indexes/41507/
B4: Для оценки потенциального реального ВВП (Potential Real GDP) мы применили фильтр Ходрика-Прескотта (HP-фильтр), который разделяет временной ряд реального ВВП на трендовую и циклическую компоненты, выделяя долгосрочные экономические тренды. Используя библиотеку statsmodels, мы рассчитали трендовую компоненту, которая была интерпретирована как потенциальный ВВП, и добавили её в DataFrame для визуализации. На графике представлены фактический (Real GDP) и потенциальный ВВП. Разрыв выпуска (Output Gap), определённый как разница между фактическим и потенциальным ВВП, был рассчитан тут.
B14: Дата | C14: ВВП в постоянных ценах | D14: ВВП в долларах (1 AUD = 0,65 USD) | E14: Потенциальный реальный ВВП | F14: Разрыв выпуска
B15: 31412 | C15: 197623 | D15: =ROUND(C15*0.65, 3) -> 128454.95 | E15: 128464.49 | F15: =ROUND((D15-E15)/E15, 3) -> 0
B16: 31502 | C16: 198991 | D16: =ROUND(C16*0.65, 3) -> 129344.15 | E16: 129697.54 | F16: =ROUND((D16-E16)/E16, 3) -> -0.003
B17: 31593 | C17: 198640 | D17: =ROUND(C17*0.65, 3) -> 129116 | E17: 130930.58 | F17: =ROUND((D17-E17)/E17, 3) -> -0.014
B18: 31685 | C18: 199145 | D18: =ROUND(C18*0.65, 3) -> 129444.25 | E18: 132163.39 | F18: =ROUND((D18-E18)/E18, 3) -> -0.021
B19: 31777 | C19: 202465 | D19: =ROUND(C19*0.65, 3) -> 131602.25 | E19: 133394.61 | F19: =ROUND((D19-E19)/E19, 3) -> -0.013
B20: 31867 | C20: 204443 | D20: =ROUND(C20*0.65, 3) -> 132887.95 | E20: 134621.17 | F20: =ROUND((D20-E20)/E20, 3) -> -0.013
B21: 31958 | C21: 207707 | D21: =ROUND(C21*0.65, 3) -> 135009.55 | E21: 135838.9 | F21: =ROUND((D21-E21)/E21, 3) -> -0.006
B22: 32050 | C22: 211445 | D22: =ROUND(C22*0.65, 3) -> 137439.25 | E22: 137042.53 | F22: =ROUND((D22-E22)/E22, 3) -> 0.003
B23: 32142 | C23: 215722 | D23: =ROUND(C23*0.65, 3) -> 140219.3 | E23: 138226.28 | F23: =ROUND((D23-E23)/E23, 3) -> 0.014
B24: 32233 | C24: 216592 | D24: =ROUND(C24*0.65, 3) -> 140784.8 | E24: 139384.61 | F24: =ROUND((D24-E24)/E24, 3) -> 0.01
B25: 32324 | C25: 216823 | D25: =ROUND(C25*0.65, 3) -> 140934.95 | E25: 140513.24 | F25: =ROUND((D25-E25)/E25, 3) -> 0.003
B26: 32416 | C26: 218569 | D26: =ROUND(C26*0.65, 3) -> 142069.85 | E26: 141608.76 | F26: =ROUND((D26-E26)/E26, 3) -> 0.003
... B169: 45473 | C169: 612180 | D169: =ROUND(C169*0.65, 3) -> 397917 | E169: 400588.7 | F169: =ROUND((D169-E169)/E169, 3) -> -0.007

Sheet Темп Базовой Инфляции
B2: Источник: https://cbonds.ru/indexes/41437/
B4: Мы взяли данные темпа базовой инфляции. Данные представлены с исключением сезонного фактора. Для получения годового (аннуализированного) показателя была использована все та же формула: (1 + r)^n - 1
B9: Дата | C9: Темп Базовой инфляции | D9: Аннуализированный Темп Базовой инфляции
B10: 31412 | C10: 2.09 | D10: =ROUND((1+C10/100)^4-1, 3) -> 0.086
B11: 31502 | C11: 2.02 | D11: =ROUND((1+C11/100)^4-1, 3) -> 0.083
B12: 31593 | C12: 1.95 | D12: =ROUND((1+C12/100)^4-1, 3) -> 0.08
B13: 31685 | C13: 1.9 | D13: =ROUND((1+C13/100)^4-1, 3) -> 0.078
B14: 31777 | C14: 1.93 | D14: =ROUND((1+C14/100)^4-1, 3) -> 0.079
B15: 31867 | C15: 1.82 | D15: =ROUND((1+C15/100)^4-1, 3) -> 0.075
B16: 31958 | C16: 1.77 | D16: =ROUND((1+C16/100)^4-1, 3) -> 0.073
B17: 32050 | C17: 1.68 | D17: =ROUND((1+C17/100)^4-1, 3) -> 0.069
B18: 32142 | C18: 1.68 | D18: =ROUND((1+C18/100)^4-1, 3) -> 0.069
B19: 32233 | C19: 1.8 | D19: =ROUND((1+C19/100)^4-1, 3) -> 0.074
B20: 32324 | C20: 1.87 | D20: =ROUND((1+C20/100)^4-1, 3) -> 0.077
B21: 32416 | C21: 1.91 | D21: =ROUND((1+C21/100)^4-1, 3) -> 0.079
... B165: 45565 | C165: 4.43 | D165: =ROUND((1+C165/100)^4-1, 3) -> 0.189

Sheet Composite Leading Indicator (CL
B2: Источник данных: https://tradingeconomics.com/australia/composite-leading-indicator#:~:text=Composite%20Leading%20Indicator%20in%20Australia,points%20in%20October%20of%201974.
B4: Индексом экономической активности мы взяли Композитный опережающий индекс - Composite Leading Indicator (CLI)
B6: CLI агрегирует опережающие экономические индикаторы, такие как заказы, занятость, разрешения на строительство и другие компоненты, которые отражают текущую и будущую экономическую активность. Данный индекс в нашей работе может служить индикатором изменений в экономике, которые затем приводят к инфляционным или дефляционным эффектам. Мы не нашли литературу, которая оценивает кривую Филлипса по CLI, но данная работа показывает взаимосвязь CLI и инфляции.
B8: Дата | C8: Composite Leading Indicator (CLI) ежемесячно | D8: Composite Leading Indicator (CLI) ежеквартально
B9: 31412 | C9: 100.0174 | D9: =C9 -> 100.0174
B10: 31443 | C10: 99.7943
B11: 31471 | C11: 99.5645
B12: 31502 | C12: 99.3348 | D12: =ROUND(SUM(C10:C12)/3, 4) -> 99.5645
B13: 31532 | C13: 99.1167
B14: 31563 | C14: 98.9299
B15: 31593 | C15: 98.7924 | D15: =ROUND(SUM(C13:C15)/3, 4) -> 98.9463
B16: 31624 | C16: 98.7347
B17: 31655 | C17: 98.784
B18: 31685 | C18: 98.945 | D18: =ROUND(SUM(C16:C18)/3, 4) -> 98.8212
B19: 31716 | C19: 99.1762
B20: 31746 | C20: 99.4194
B21: 31777 | C21: 99.6369 | D21: =ROUND(SUM(C19:C21)/3, 4) -> 99.4108
B22: 31808 | C22: 99.8413
B23: 31836 | C23: 100.0605
B24: 31867 | C24: 100.3109 | D24: =ROUND(SUM(C22:C24)/3, 4) -> 100.0709
B25: 31897 | C25: 100.5793
B26: 31928 | C26: 100.8432
B27: 31958 | C27: 101.0707 | D27: =ROUND(SUM(C25:C27)/3, 4) -> 100.8311
B28: 31989 | C28: 101.2283
B29: 32020 | C29: 101.2768
B30: 32050 | C30: 101.2064 | D30: =ROUND(SUM(C28:C30)/3, 4) -> 101.2372
B31: 32081 | C31: 101.0928
B32: 32111 | C32: 101.007
B33: 32142 | C33: 101.0048 | D33: =ROUND(SUM(C31:C33)/3, 4) -> 101.0349
A34: 88 | B34: 32173 | C34: 101.0829
B35: 32201 | C35: 101.2081
B36: 32233 | C36: 101.3773 | D36: =ROUND(SUM(C34:C36)/3, 4) -> 101.2228
B37: 32263 | C37: 101.5738
B38: 32294 | C38: 101.7785
B39: 32324 | C39: 101.9837 | D39: =ROUND(SUM(C37:C39)/3, 4) -> 101.7787
B40: 32355 | C40: 102.1708
B41: 32386 | C41: 102.3041
B42: 32416 | C42: 102.3492 | D42: =ROUND(SUM(C40:C42)/3, 4) -> 102.2747
B43: 32447 | C43: 102.2828
B44: 32477 | C44: 102.1132
...
